<?xml version="1.0" ?>
<!-- Generated using onshape-to-robot -->
<!-- Onshape https //cad.onshape.com/documents/3dc4b4763b6718c02dc70986/w/79ac6331923ba2fd9582710d/e/a51fdc22539c66f5617fdfdf -->
<robot xmlns:xacro="http://ros.org/wiki/xacro" name="ball_butler">
  <!-- Link base -->
  <link name="base">
    <inertial>
      <origin xyz="0 0 0" rpy="0 0 0"/>
      <mass value="1e-09"/>
      <inertia ixx="1e-09" ixy="0" ixz="0" iyy="1e-09" iyz="0" izz="1e-09"/>
    </inertial>
    <!-- Part base -->
    <visual>
      <origin xyz="0 0 0" rpy="0 0 0"/>
      <geometry>
			  <mesh filename="package://ball_butler_support/mesh/base.stl"/>
      </geometry>
      <material name="base_material">
        <color rgba="0.615686 0.811765 0.929412 1"/>
      </material>
    </visual>
    <collision>
      <origin xyz="0 0 0" rpy="0 0 0"/>
      <geometry>
        <mesh filename="package://ball_butler_support/mesh/base.stl"/>
      </geometry>
    </collision>
  </link>
  <!-- Link lid -->
  <link name="lid">
    <inertial>
      <origin xyz="0 0 0" rpy="0 0 0"/>
      <mass value="1e-09"/>
      <inertia ixx="1e-09" ixy="0" ixz="0" iyy="1e-09" iyz="0" izz="1e-09"/>
    </inertial>
    <!-- Part lid -->
    <visual>
      <origin xyz="0 0 0.025" rpy="3.14159 -0 0"/>
      <geometry>
        <mesh filename="package://ball_butler_support/mesh/lid.stl"/>
      </geometry>
      <material name="lid_material">
        <color rgba="0.615686 0.811765 0.929412 1"/>
      </material>
    </visual>
    <collision>
      <origin xyz="0 0 0.025" rpy="3.14159 -0 0"/>
      <geometry>
        <mesh filename="package://ball_butler_support/mesh/lid.stl"/>
      </geometry>
    </collision>
  </link>
  <!-- Link pitch -->
  <link name="pitch">
    <inertial>
      <origin xyz="0 0 0" rpy="0 0 0"/>
      <mass value="1e-09"/>
      <inertia ixx="1e-09" ixy="0" ixz="0" iyy="1e-09" iyz="0" izz="1e-09"/>
    </inertial>
    <!-- Part pitch -->
    <visual>
      <origin xyz="0 0 0" rpy="-1.5708 0 0"/>
      <geometry>
        <mesh filename="package://ball_butler_support/mesh/pitch.stl"/>
      </geometry>
      <material name="pitch_material">
        <color rgba="0.615686 0.811765 0.929412 1"/>
      </material>
    </visual>
    <collision>
      <origin xyz="0 0 0" rpy="-1.5708 0 0"/>
      <geometry>
        <mesh filename="package://ball_butler_support/mesh/pitch.stl"/>
      </geometry>
    </collision>
  </link>
  <!-- Link hand -->
  <link name="hand">
    <inertial>
      <origin xyz="0 0 0" rpy="0 0 0"/>
      <mass value="1e-09"/>
      <inertia ixx="1e-09" ixy="0" ixz="0" iyy="1e-09" iyz="0" izz="1e-09"/>
    </inertial>
    <!-- Part hand -->
    <visual>
      <origin xyz="0.01 0 0" rpy="-3.14159 0 0"/>
      <geometry>
        <mesh filename="package://ball_butler_support/mesh/hand.stl"/>
      </geometry>
      <material name="hand_material">
        <color rgba="0.615686 0.811765 0.929412 1"/>
      </material>
    </visual>
    <collision>
      <origin xyz="0.01 0 0" rpy="-3.14159 0 0"/>
      <geometry>
        <mesh filename="package://ball_butler_support/mesh/hand.stl"/>
      </geometry>
    </collision>
  </link>
  <!-- Joint from pitch to hand -->
  <joint name="throw" type="prismatic">
    <origin xyz="-0.01 0.0949984 0" rpy="1.5708 -1.5708 0"/>
    <parent link="pitch"/>
    <child link="hand"/>
    <axis xyz="0 0 1"/>
    <limit effort="10" velocity="10" lower="-1" upper="1"/>
  </joint>
  <!-- Joint from lid to pitch -->
  <joint name="pitch" type="revolute">
    <origin xyz="0.041 0.025 -0.0135" rpy="-1.5708 0.771723 0"/>
    <parent link="lid"/>
    <child link="pitch"/>
    <axis xyz="0 0 1"/>
    <limit effort="10" velocity="10" lower="-3.141592653589793" upper="3.141592653589793"/>
  </joint>
  <!-- Joint from base to lid -->
  <joint name="yaw" type="revolute">
    <origin xyz="0 0 0.0565" rpy="3.14159 -0 -3.07134"/>
    <parent link="base"/>
    <child link="lid"/>
    <axis xyz="0 0 1"/>
    <limit effort="10" velocity="10" lower="-3.141592653589793" upper="3.141592653589793"/>
  </joint>
</robot>
